Workbook
Name GliderTypes: 'Glider Model'!$D$122:$D$123

Sheet Revision Info
B1: Revision Information
A3: Revision | B3: Date | C3: ECO | D3: Revised By | E3: Description
B4: 38398 | D4: Tim Scholz | E4: Addition of top level worksheet.
B5: 38517 | D5: Tim Scholz | E5: Added Revision worksheet. Modified for addition of Tadarin Battery packs. Added additional functionality to the top level for error checking and additional calculations.
B6: 38518 | D6: Tim Scholz | E6: Added new 1000 meter pump numbers
B7: 38617 | D7: Tim Scholz | E7: Changed Li batteries from c-cell to DD-cells
B8: 38963 | D8: Tim Scholz | E8: Changed Alkaline battery derating curve ot be less aggressive. Added battery loss due to pump current.
B9: 39023 | D9: Tim Scholz | E9: Added battery loss for Lithium cells. Tadarin assumed to be equal.
B10: 39490 | D10: Tim Scholz | E10: Changed Li batteries to CSC C-cells
B11: 39591 | D11: Tim Scholz | E11: Changed Li batteries to include DD-cells
B12: 39960 | D12: C Jones | E12: BAM at 30 ma 40% duty for deep
B13: 39961 | D13: C Jones | E13: BAM at 30 ma 20% duty for deep
B14: 40695 | D14: H Fargher | E14: Added remaining days & distance, as well as calculated data transmission
B15: 40708 | D15: H Fargher | E15: Ensured use for both 200m and 1000m gliders with user-defined additional sensors.
B16: 40806 | D16: H Fargher | E16: Accounted for acoustic-modem communicaton with data nodes.
A17: A | B17: 40807 | C17: ECO-428 | D17: D Pingal | E17: Fixed current consumption numbers for attitude, altutide
A18: 4 | B18: 40809 | D18: D Pingal | E18: Fixed optode, spare sensors calculations
A19: B Draft | B19: 40961 | D19: D Pingal | E19: Merged / corrected coastal vs Open Ocean energy capacity calculations
A20: B | B20: 40973 | D20: D Pingal | E20: Fixed sensor calculations, buoyancy pump power
A21: C | B21: 41201 | D21: D Pingal | E21: Incorporated OO test data, added Amp hr / day

Sheet User Guide

Sheet Glider Parameters
C3: Slocum Glider Endurance Tool
C5: Mission Parameters | F5: =IF(F6>F17,"Error! Profile Too Deep!","") | H5: Calculated Parameters
E6: Maximum Profile Depth (Meters): | F6: 200 | J6: Trajectory Angle (Degrees): | K6: =ATAN(F9/F8)*180/PI() -> 21.370622
E7: Minimum Profile Depth (Meters): | F7: 1 | J7: Profile Duration (Minutes): | K7: =(F6-F7)/F9*2/60 -> 73.703704
E8: Horizontal Velocity (Meters/Sec.): | F8: 0.23 | J8: Profile Distance (Meters): | K8: =F8*K7*60 -> 1017.1111
E9: Vertical Velocity (Meters/Sec.): | F9: 0.09 | J9: Number of Profiles Between Surfacing: | K9: =IF(F11="n",F12,IF(F11="t",F12/K7,F12/K8)) -> 6
C10: Profile Parameters: | J10: Time Between Surfacing (minutes): | K10: =IF(F11="n",F12*K7+2*F7/F9/60,IF(F11="t",F12,F12/F8/60)) -> 442.59259
E11: T = Time, N = Profile Number, D = Distance: | F11: N | J11: Distance Between Surfacing (km): | K11: =K10*F8/1000*60 -> 6.1077778
E12: =IF(F11="n","Number of Profiles before surface:",IF(F11="t","Time before surface (Minutes):",IF(F11="d","Distance before surface (Meters):","ERROR! Enter T, N, or D for Profile Type."))) -> Number of Profiles before surface: | F12: 6 | K12: ='Glider Model'!Q6 -> 26768508
E13: Surface Time (Minutes): | F13: 15 | K13: ='Glider Model'!Q7 -> 119.32333
E14: Avg. Operating Temperature (C): | F14: 8 | K14: ='Glider Model'!Q8 -> 2293.4019
C16: Glider Configuration | K16: ='Glider Model'!Q9 -> 119.32333
E17: Pump Installed (200 or 1000 Meter): | F17: 1000 | K17: ='Glider Model'!Q10 -> 2293.4019
C18: 1 = enabled | E18: Pinger | F18: 0 | H18: =IF(F18=0,"",IF(F18=1,"","ERROR! Please enter 0 or 1.")) | K18: =F27*10*'Glider Model'!Z8 -> 689.91
C19: 0 = disabled | E19: Altimeter | F19: 1 | J19: Ah per day (Slocum & Standard Sensors): | K19: ='Glider Model'!T15*(24/10.8) -> 5.7699567
E20: Freewave | F20: 1 | J20: Total Ah per day (Thruster and Extra Sensors) | K20: =(K43/100*11.2)+(F50*1.6)+(F51*11.2)+(F52*1.6)+(F53*6.4)+K19 -> 25.769957
E21: PTT | F21: 0
C22: Glider Type | E22: Coastal
H23: Calculated Data Transmission
C24: Battery Configuration | H24: =IF(F26<>"lc",IF(F26<>"ld",IF(F26<>"a",IF(F26<>"t","ERROR! Enter Battery Type.",""),""),""),"")
C25: Battery Chemistry: | I25: Daily transmission (kbytes/day): | K25: ='Glider Model'!Y4 -> 13.341901
E26: A=Alkaline, Ld=Li DD: | F26: Ld | I26: Total transmission (kbytes): | K26: ='Glider Model'!Y5 -> 1592
E27: =IF(F26="t","Number of Li Packs:",IF(F26="a","Number of C-Cells",IF(F26="lc","Number of C-Cells:",IF(F26="ld","Number of DD-Cells:","ERROR")))) -> Number of DD-Cells: | F27: =IF($E$22="Coastal",78,114) -> 78
C28: Battery type: | D28: R=Rechargeable, P= Primary | E28: P | H28: Endurance
C29: Extended Energy Bay: | D29: 1=available, 0=absent | E29: 0
E30: =IF(AND(E29>0, F51>0), "Error: EK80 integration can't support Extended Energy bay", "") | I30: Total number of days | K30: =ROUND(IF(AND(E28="P",E29=0),550,IF(AND(E28="P",E29=1),800,IF(AND(E28="R",E29=0),215,IF(AND(E28="R",E29=1),300,0))))/K20,0) -> 21
C31: Battery Usage | I31: Approximate Distance covered (km) | K31: =20*K30 -> 420
E32: Remaining energy (%): | F32: 100
C34: Standard Science Configuration
K35: 0
C36: 1 = enabled | E36: CTD | F36: 1 | K36: 0
C37: 0 = disabled | E37: Motherboard | F37: 0.5 | K37: 1
C38: 0.N = fraction enabled
E39: Persistor | F39: 0.5
E40: Aanderaa Optode | F40: 1
E41: Explorer 600 kHz DVL | F41: 0
E42: FLBBCD-SLK | F42: 1 | H42: Thruster Use (at 7W)
E43: Biospherical QSP-2150 | F43: 0 | J43: Usage (%): | K43: 50
C46: Extra Sensors
C48: 1 = enabled
...

Sheet Glider Model
B1: Electric Glider Power Summary | L1: Minimum Depth: | M1: ='Glider Parameters'!F7 -> 1 | S1: Battery Derating Information | Z1: Pump time | AC1: 0.001707
F2: Energy Configuration | J2: Mission Parameters | M2: =IF(M3>M9,"Error! Profile Too Deep!","") | N2: Calculated Parameters (Glider) | S2: Battery Type: | T2: ='Glider Parameters'!F26 -> Ld | V2: Calculated Data Transmission | Z2: 200 m | AC2: -0.0765
B3: Origination Date: | D3: 41201 | F3: Main | H3: Number of Li Packs: | I3: =IF(T2="Ld",'Glider Parameters'!F27,0) -> 78 | L3: Profile Depth (Meters): | M3: ='Glider Parameters'!F6 -> 200 | P3: Trajectory Angle (Degrees): | Q3: =ATAN(M5/M4)*180/PI() -> 21.370622 | S3: Temp | U3: derating factor | Z3: =IF(M3<34,17,0.00074*M3^2-0.0364*M3+17.4) -> 39.72 | AC3: 1.239
B4: Last Edited: | C4: by: | D4: dp | H4: Number of C-Cells: | I4: =IF(T2="Ld",0,'Glider Parameters'!F27) -> 0 | L4: Horizontal Velocity (Meters/Sec.): | M4: ='Glider Parameters'!F8 -> 0.23 | P4: Profile Duration (Minutes): | Q4: ='Glider Parameters'!K7 -> 73.703704 | R4: =Q7*24*60/(Q4*M6+M7)*M6 -> 2254.8194 | S4: (C) | T4: alkaline | U4: lithium | V4: Daily transmission (kbytes/day): | Y4: =SUM(X16, X31, X45) + R110 -> 13.341901 | Z4: 1000 m | AC4: -8.692
H5: Stored Energy (Joules): | I5: =30000*I4+I3*388000 -> 30264000 | L5: Vertical Velocity (Meters/Sec.): | M5: ='Glider Parameters'!F9 -> 0.09 | P5: Profile Distance (Meters): | Q5: ='Glider Parameters'!K8 -> 1017.1111 | S5: 0 | T5: 0.7 | U5: 0.77 | V5: Total transmission (kbytes): | Y5: =SUM(Y16, Y31, Y45) + (Q7*R110) -> 1592 | Z5: =IF(M3<600, 199, 0.00013*M3^2-0.12*M3+225)*F116 -> 166.49535 | AC5: 23.42
B6: Comment: | D6: is measured Data | F6: Emergency | H6: Number of D-Cells: | I6: 0 | L6: # of Profiles before surface: | M6: ='Glider Parameters'!F12 -> 6 | P6: Derated Energy (Joules): | Q6: =I5*Z8*IF(Z9>1,1,Z9) -> 26768508 | S6: 10 | T6: 0.85 | U6: 0.88
D7: is calculated data | H7: Number of C-Cells: | I7: ='Glider Parameters'!F29 -> 0 | L7: Surface Time (Minutes): | M7: ='Glider Parameters'!F13 -> 15 | P7: Calculated Duration (Days): | Q7: =Q6/24/3600/(T15 + R112) -> 119.32333 | S7: 20 | T7: 1 | U7: 1
H8: Stored Energy (Joules): | I8: =I7*30000+I6*60000 -> 0 | L8: Avg. Operating Temperature (C): | M8: ='Glider Parameters'!F14 -> 8 | P8: Calculated distance (km): | Q8: =Q7*24*3600*Q4*M6/(Q4*M6+M7)*M4/1000 -> 2293.4019 | U8: Temperature Derating (%): | Z8: =IF(T2="a",IF(M8<20,0.7+M8*0.015,1),M8*0.1925/20+0.8075) -> 0.8845
H9: End of Life Voltage (VDC): | I9: ='Glider Parameters'!F28 -> 0 | L9: Pump Installed (100, 200, or 1000 Meter): | M9: ='Glider Parameters'!F17 -> 1000 | N9: Calculated Remaining Duration (Days): | Q9: =Q7 * I10 / 100 -> 119.32333 | U9: End Voltage Derating (%): | Z9: =IF(T2="a",AC$1*I9^4+AC$2*I9^3+AC$3*I9^2+AC$4*I9+AC$5,IF(T2="l",IF(I9<=12.1,1,0.83),IF(I9<=13,1,0.83))) -> 1
B10: Average battery voltage (VDC): | D10: =IF(T$2="a",12,IF(LEFT(T$2, 1)="l",10.8,14.4)) -> 10.8 | F10: Useage | H10: Remaining Energy (%): | I10: ='Glider Parameters'!F32 -> 100 | N10: Calculated Remaining Distance (km): | Q10: =Q8 * I10 / 100 -> 2293.4019
P11: Per Surface Period Data
K12: Profile Time | M12: Surface Time | O12: Total | S12: Rolled Up Data | W12: Sensor Data
B13: Glider Component | D13: On V avg. | E13: On I avg | F13: On P avg. | G13: Current at | H13: 10 VDC P | I13: Off Current | J13: Off Power | K13: On Time | L13: Interval | M13: On Time | N13: Interval | O13: On Time | P13: Off Time | Q13: Duty Cycle | R13: On Energy | S13: Off Energy | T13: Energy/Sec. | U13: Percent | V13: Record | W13: Period | X13: Daily | Y13: Total
C14: Level | D14: (VDC) | E14: (A) | F14: (W) | G14: 10 VDC (A) | H14: (W) | I14: 13 VDC (A) | J14: 13 VDC (W) | K14: (Sec) | L14: (Sec) | M14: (Sec) | N14: (Sec) | O14: (Sec) | P14: (Sec) | Q14: (%) | R14: (J) | S14: (J) | T14: (J/s) | U14: of Total | V14: (Bytes) | W14: (Sec) | X14: (KBytes) | Y14: (Kbytes) | Z14: Multiplier | AA14: Comments | AB14: Potential Improvements
A15: 1 | B15: Glider Top Level | R15: =SUM(R16,R31,R45) -> 77913.611 | S15: =SUM(S16,S31,S45) -> 13.530482 | T15: =SUM(T16,T31,T45) -> 2.5964805 | U15: =T15/T$15 -> 1
A16: =A15+1 -> 2 | B16: FWD Chassis | C16: 1 | R16: =SUM(R17,R22,R25,R26,R27,R30,) -> 42772.955 | S16: =SUM(S17,S22,S25,S26,S27,S30,) -> 0.99743248 | T16: =SUM(T17,T22,T25,T26,T27,T30,) -> 1.4219158 | U16: =T16/T$15 -> 0.54763198 | X16: =SUM(X17:X30) -> 0 | Y16: =SUM(Y17:Y30) -> 0 | Z16: 1
A17: =A16+1 -> 3 | B17: Buoyancy Pump | C17: 2 | R17: =SUM(R18:R21) -> 33245.18 | S17: =SUM(S18:S21) -> 0.00041147375 | T17: =SUM(T18:T21) -> 1.2118535 | U17: =T17/T$15 -> 0.46672928 | Z17: 1
A18: =A17+1 -> 4 | B18: Feedback Pot | C18: 3 | D18: 2.5 | E18: 0.00025 | F18: =D18*E18 -> 0.000625 | G18: 0.00025 | H18: 0.000625 | I18: 0 | J18: 0 | K18: =K19+K20 -> 481.63535 | L18: =L19 -> 4422.2222 | M18: 0 | N18: 600 | O18: =(Q$4*60*M$6)/L18*K18+M$7*60/N18*M18 -> 2889.8121 | P18: =(Q$4*M$6+M$7)*60-O18 -> 24543.521 | Q18: =O18/(O18+P18) -> 0.10533944 | R18: =F18*O18 -> 1.8061325 | S18: =J18*P18 -> 0 | T18: =((S18+R18)/(Q$4*M$6+M$7)/60)*Z18 -> 6.5837152e-05 | U18: =T18/T$15 -> 2.5356305e-05 | Z18: 1
A19: =A18+1 -> 5 | B19: Pump | C19: 3 | D19: =$D$10 -> 10.8 | E19: =IF(M9=1000,1.672+0.006*M3,(3970*M3/M9+39.5)/1000) -> 2.872 | F19: =D19*E19 -> 31.0176 | I19: 0 | J19: 0 | K19: =IF(M9=200,Z3,Z5) -> 166.49535 | L19: =Q4*60 -> 4422.2222 | M19: 0 | N19: =M$7*60 -> 900 | O19: =(Q$4*60*M$6)/L19*K19+M$7*60/N19*M19 -> 998.97207 | P19: =(Q$4*M$6+M$7)*60-O19 -> 26434.361 | Q19: =O19/(O19+P19) -> 0.036414535 | R19: =F19*O19 -> 30985.716 | S19: =J19*P19 -> 0 | T19: =((S19+R19)/(Q$4*M$6+M$7)/60)*Z19 -> 1.1294915 | U19: =T19/T$15 -> 0.43500865 | Z19: 1 | AB19: Increase efficiency of motor and transmission
A20: =A19+1 -> 6 | B20: Pump Retraction | C20: 3 | D20: =$D$10 -> 10.8 | E20: =IF(M9=1000,0.11,0.198) -> 0.11 | F20: =D20*E20 -> 1.188 | K20: =IF(M9=100,8,IF(M9=200,17,IF(M1<50,320-4.86*M1,0))) -> 315.14 | L20: =Q4*60 -> 4422.2222 | M20: 0 | N20: =M$7*60 -> 900 | O20: =(Q$4*60*M$6)/L20*K20+M$7*60/N20*M20 -> 1890.84 | P20: =(Q$4*M$6+M$7)*60-O20 -> 25542.493 | Q20: =O20/(O20+P20) -> 0.068924909 | R20: =F20*O20 -> 2246.3179 | S20: =J20*P20 -> 0 | T20: =((S20+R20)/(Q$4*M$6+M$7)/60)*Z20 -> 0.081882792 | U20: =T20/T$15 -> 0.03153607 | Z20: 1 | AB20: Self returning piston?
A21: =A20+1 -> 7 | B21: Brake | C21: 3 | D21: =$D$10 -> 10.8 | E21: 0.6 | F21: =D21*E21 -> 6.48 | I21: 1e-09 | J21: =I21*15 -> 1.5e-08 | K21: 0.25 | L21: =Q$4*60 -> 4422.2222 | M21: 0.25 | N21: =M$7*60 -> 900 | O21: =(Q$4*60*M$6)/L21*K21+M$7*60/N21*M21 -> 1.75 | P21: =(Q$4*M$6+M$7)*60-O21 -> 27431.583 | Q21: =O21/(O21+P21) -> 6.3791009e-05 | R21: =F21*O21 -> 11.34 | S21: =J21*P21 -> 0.00041147375 | T21: =((S21+R21)/(Q$4*M$6+M$7)/60)*Z21 -> 0.00041338073 | U21: =T21/T$15 -> 0.0001592081 | Z21: 1
A22: =A21+1 -> 8 | B22: Pitch Motor | C22: 2 | R22: =SUM(R23:R24) -> 870.36508 | S22: =SUM(S23:S24) -> 0.000405512 | T22: =SUM(T23:T24) -> 0.031726567 | U22: =T22/T$15 -> 0.012219066 | Z22: 1
A23: =A22+1 -> 9 | B23: Feedback Pot | C23: 3 | D23: 2.5 | E23: 0.00025 | F23: =D23*E23 -> 0.000625 | G23: 0.00025 | H23: 0.000625 | I23: 0 | J23: 0 | K23: =K24 -> 66.533333 | L23: =Q$4*60 -> 4422.2222 | M23: 0 | N23: =M$7*60 -> 900 | O23: =(Q$4*60*M$6)/L23*K23+M$7*60/N23*M23 -> 399.2 | P23: =(Q$4*M$6+M$7)*60-O23 -> 27034.133 | Q23: =O23/(O23+P23) -> 0.01455164 | R23: =F23*O23 -> 0.2495 | S23: =J23*P23 -> 0 | T23: =((S23+R23)/(Q$4*M$6+M$7)/60)*Z23 -> 9.0947752e-06 | U23: =T23/T$15 -> 3.502732e-06 | Z23: 1
A24: =A23+1 -> 10 | B24: Motor | C24: 3 | D24: =$D$10 -> 10.8 | E24: 0.17778052 | F24: 2.1796483 | G24: 0.16670107 | H24: 1.5516735 | I24: 1e-09 | J24: =I24*15 -> 1.5e-08 | K24: =40+L24*0.006 -> 66.533333 | L24: =Q$4*60 -> 4422.2222 | M24: 0 | N24: =M$7*60 -> 900 | O24: =(Q$4*60*M$6)/L24*K24+M$7*60/N24*M24 -> 399.2 | P24: =(Q$4*M$6+M$7)*60-O24 -> 27034.133 | Q24: =O24/(O24+P24) -> 0.01455164 | R24: =F24*O24 -> 870.11558 | S24: =J24*P24 -> 0.000405512 | T24: =((S24+R24)/(Q$4*M$6+M$7)/60)*Z24 -> 0.031717472 | U24: =T24/T$15 -> 0.012215563 | Z24: 1
A25: =A24+1 -> 11 | B25: Altimeter | C25: 2 | D25: =$D$10 -> 10.8 | E25: 0.034 | F25: =D25*E25 -> 0.3672 | I25: 0 | J25: 0 | K25: =L25*0.5*3.3/4 -> 1824.1667 | L25: =Q$4*60 -> 4422.2222 | M25: 0 | N25: =M$7*60 -> 900 | O25: =(Q$4*60*M$6)/L25*K25+M$7*60/N25*M25 -> 10945 | P25: =(Q$4*M$6+M$7)*60-O25 -> 16488.333 | Q25: =O25/(O25+P25) -> 0.39896719 | R25: =F25*O25 -> 4019.004 | S25: =J25*P25 -> 0 | T25: =((S25+R25)/(Q$4*M$6+M$7)/60)*Z25 -> 0.14650075 | U25: =T25/T$15 -> 0.056422821 | Z25: =IF('Glider Parameters'!$E$22="Coastal",G$122,G$123)*'Glider Parameters'!F19 -> 1
A26: =A25+1 -> 12 | B26: Pinger Module | C26: 2 | D26: =$D$10 -> 10.8 | E26: 0.14 | F26: 70 | I26: 2.8e-06 | J26: =I26*13 -> 3.64e-05 | K26: 0.016 | L26: 8 | M26: =0.016*360/60/M$7 -> 0.0064 | N26: 8 | O26: =(Q$4*60*M$6)/L26*K26+M$7*60/N26*M26 -> 53.786667 | P26: =(Q$4*M$6+M$7)*60-O26 -> 27379.547 | Q26: =O26/(O26+P26) -> 0.0019606318 | R26: =F26*O26 -> 3765.0667 | S26: =J26*P26 -> 0.9966155 | T26: =((S26+R26)/(Q$4*M$6+M$7)/60)*Z26 -> 0 | U26: =T26/T$15 -> 0 | Z26: ='Glider Parameters'!F18 -> 0
A27: =A26+1 -> 13 | B27: Battery Losses | C27: 2 | R27: =SUM(R28:R29) -> 873.22751 | S27: =SUM(S28:S29) -> 0 | T27: =SUM(T28:T29) -> 0.031830893 | U27: =T27/T$15 -> 0.012259246 | Z27: 1
A28: =A27+1 -> 14 | B28: Battery Leakage | C28: 3 | D28: =$D$10 -> 10.8 | E28: =Q$6/365/2/24/3600/D28*0.075 -> 0.0029473049 | F28: =E28*D28 -> 0.031830893 | K28: =L28 -> 4422.2222 | L28: =Q$4*60 -> 4422.2222 | M28: =N28 -> 900 | N28: =M$7*60 -> 900 | O28: =(Q$4*60*M$6)/L28*K28+M$7*60/N28*M28 -> 27433.333 | P28: =(Q$4*M$6+M$7)*60-O28 -> 0 | Q28: =O28/(O28+P28) -> 1 | R28: =F28*O28 -> 873.22751 | S28: =J28*P28 -> 0 | T28: =((S28+R28)/(Q$4*M$6+M$7)/60)*Z28 -> 0.031830893 | U28: =T28/T$15 -> 0.012259246 | Z28: 1
A29: =A28+1 -> 15 | B29: Battery Loss | C29: 3 | D29: =IF(I4=0,0,IF(T2="a",100/I4*E29,1.35/I4*E29)) -> 0 | E29: =E19 -> 2.872 | F29: =E29*D29 -> 0 | K29: =K19 -> 166.49535 | L29: =Q$4*60 -> 4422.2222 | M29: =M19 -> 0 | N29: =M$7*60 -> 900 | O29: =(Q$4*60*M$6)/L29*K29+M$7*60/N29*M29 -> 998.97207 | P29: =(Q$4*M$6+M$7)*60-O29 -> 26434.361 | Q29: =O29/(O29+P29) -> 0.036414535 | R29: =F29*O29 -> 0 | S29: =J29*P29 -> 0 | T29: =((S29+R29)/(Q$4*M$6+M$7)/60)*Z29 -> 0 | U29: =T29/T$15 -> 0 | Z29: 1
A30: =A29+1 -> 16 | B30: Leak Detector | C30: 2 | D30: 5 | E30: =D30/100000 -> 5e-05 | F30: =E30*D30 -> 0.00025 | K30: 0.065 | L30: 4 | M30: 0.065 | N30: 4 | O30: =(Q$4*60*M$6)/L30*K30+M$7*60/N30*M30 -> 445.79167 | P30: =(Q$4*M$6+M$7)*60-O30 -> 26987.542 | Q30: =O30/(O30+P30) -> 0.01625 | R30: =F30*O30 -> 0.11144792 | S30: =J30*P30 -> 0 | T30: =((S30+R30)/(Q$4*M$6+M$7)/60)*Z30 -> 4.0625e-06 | U30: =T30/T$15 -> 1.564618e-06 | Z30: 1
A31: =A30+1 -> 17 | B31: Science Bay | C31: 1 | R31: =SUM(R32,R36:R41,R44) -> 28744.925 | S31: =SUM(S32,S36:S41,S44) -> 0.162 | T31: =SUM(T32,T36:T41,T44) -> 0.94335917 | U31: =T31/T$15 -> 0.36332226 | X31: =SUM(X33:X44) -> 13.341901 | Y31: =SUM(Y33:Y44) -> 1592 | Z31: 1
A32: =A31+1 -> 18 | B32: Quad UART | C32: 2 | R32: =SUM(R33:R35) -> 5731.2 | S32: =SUM(S33:S35) -> 0 | T32: =SUM(T33:T35) -> 0.10445687 | U32: =T32/T$15 -> 0.040230175 | Z32: 1
A33: =A32+1 -> 19 | B33: UART | C33: 3 | D33: =$D$10 -> 10.8 | E33: 0.0046 | F33: =D33*E33 -> 0.04968 | K33: =MAX(K34,K36:K38) -> 4422.2222 | L33: =Q$4*60 -> 4422.2222 | M33: 0 | N33: =M$7*60 -> 900 | O33: =(Q$4*60*M$6)/L33*K33+M$7*60/N33*M33 -> 26533.333 | P33: =(Q$4*M$6+M$7)*60-O33 -> 900 | Q33: =O33/(O33+P33) -> 0.9671932 | R33: =F33*O33 -> 1318.176 | S33: =J33*P33 -> 0 | T33: =((S33+R33)/(Q$4*M$6+M$7)/60)*Z33 -> 0.024025079 | U33: =T33/T$15 -> 0.0092529403 | Z33: ='Glider Parameters'!F37 -> 0.5
A34: =A33+1 -> 20 | B34: U4S | C34: 3 | D34: =$D$10 -> 10.8 | E34: 0.0181 | F34: =D34*E34 -> 0.19548 | K34: =L34*'Glider Parameters'!F38 -> 0 | L34: =Q$4*60 -> 4422.2222 | M34: 0 | N34: =M$7*60 -> 900 | O34: =(Q$4*60*M$6)/L34*K34+M$7*60/N34*M34 -> 0 | P34: =(Q$4*M$6+M$7)*60-O34 -> 27433.333 | Q34: =O34/(O34+P34) -> 0 | R34: =F34*O34 -> 0 | S34: =J34*P34 -> 0 | T34: =((S34+R34)/(Q$4*M$6+M$7)/60)*Z34 -> 0 | U34: =T34/T$15 -> 0 | Z34: ='Glider Parameters'!F38 -> 0 | AA34: 0
A35: =A34+1 -> 21 | B35: Persistor | C35: 3 | D35: =$D$10 -> 10.8 | E35: 0.0154 | F35: =D35*E35 -> 0.16632 | K35: =MAX(K33,K34) -> 4422.2222 | L35: =Q$4*60 -> 4422.2222 | M35: 0 | N35: =M$7*60 -> 900 | O35: =(Q$4*60*M$6)/L35*K35+M$7*60/N35*M35 -> 26533.333 | P35: =(Q$4*M$6+M$7)*60-O35 -> 900 | Q35: =O35/(O35+P35) -> 0.9671932 | R35: =F35*O35 -> 4413.024 | S35: =J35*P35 -> 0 | T35: =((S35+R35)/(Q$4*M$6+M$7)/60)*Z35 -> 0.080431786 | U35: =T35/T$15 -> 0.030977235 | Z35: ='Glider Parameters'!F39 -> 0.5 | AA35: Note: Current measured using CONSCI subroutine
A36: =A34+1 -> 21 | B36: Optode | C36: 2 | D36: 5 | E36: 0.02 | F36: =D36*E36 -> 0.1 | K36: =L36*'Glider Parameters'!F40 -> 4422.2222 | L36: =Q$4*60 -> 4422.2222 | M36: 0 | N36: =M$7*60 -> 900 | O36: =(Q$4*60*M$6)/L36*K36+M$7*60/N36*M36 -> 26533.333 | P36: =(Q$4*M$6+M$7)*60-O36 -> 900 | Q36: =O36/(O36+P36) -> 0.9671932 | R36: =F36*O36 -> 2653.3333 | S36: =J36*P36 -> 0 | T36: =((S36+R36)/(Q$4*M$6+M$7)/60)*Z36 -> 0.09671932 | U36: =T36/T$15 -> 0.037250162 | V36: 40 | W36: 1 | X36: =Y36 / Q7 -> 8.8946005 | Y36: =O36*V36/(1000*W36) -> 1061.3333 | Z36: ='Glider Parameters'!F40 -> 1
A37: =A35+1 -> 22 | B37: TRDI Explorer DVL | C37: 2 | D37: =$D$10 -> 10.8 | E37: 0.185 | F37: =D37*E37 -> 1.998 | K37: =L37*'Glider Parameters'!F41 -> 0 | L37: =Q$4*60 -> 4422.2222 | M37: 0 | N37: =M$7*60 -> 900 | O37: =(Q$4*60*M$6)/L37*K37+M$7*60/N37*M37 -> 0 | P37: =(Q$4*M$6+M$7)*60-O37 -> 27433.333 | Q37: =O37/(O37+P37) -> 0 | R37: =F37*O37 -> 0 | S37: =J37*P37 -> 0 | T37: =((S37+R37)/(Q$4*M$6+M$7)/60)*Z37 -> 0 | U37: =T37/T$15 -> 0 | V37: 819 | W37: 30 | X37: =Y37 / Q7 -> 0 | Y37: =O37*V37/(1000*W37) -> 0 | Z37: ='Glider Parameters'!F41 -> 0
A38: =A37+1 -> 23 | B38: FLBBCD-SLK | C38: 2 | D38: =$D$10 -> 10.8 | E38: 0.049 | F38: =D38*E38 -> 0.5292 | K38: =L38*'Glider Parameters'!F42 -> 4422.2222 | L38: =Q$4*60 -> 4422.2222 | M38: 0 | N38: =M$7*60 -> 900 | O38: =(Q$4*60*M$6)/L38*K38+M$7*60/N38*M38 -> 26533.333 | P38: =(Q$4*M$6+M$7)*60-O38 -> 900 | Q38: =O38/(O38+P38) -> 0.9671932 | R38: =F38*O38 -> 14041.44 | S38: =J38*P38 -> 0 | T38: =((S38+R38)/(Q$4*M$6+M$7)/60)*Z38 -> 0.51183864 | U38: =T38/T$15 -> 0.19712786 | V38: 8 | W38: 1 | X38: =Y38/Q7 -> 1.7789201 | Y38: =O38*V38/(1000*W38) -> 212.26667 | Z38: ='Glider Parameters'!F42 -> 1
A39: =A38+1 -> 24 | B39: Bioshperical QSP-2150 | C39: 2 | D39: =$D$10 -> 10.8 | E39: 0.0417 | F39: =D39*E39 -> 0.45036 | K39: =L39*'Glider Parameters'!F43 -> 0 | L39: =Q$4*60 -> 4422.2222 | M39: 0 | N39: =M$7*60 -> 900 | O39: =(Q$4*60*M$6)/L39*K39+M$7*60/N39*M39 -> 0 | P39: =(Q$4*M$6+M$7)*60-O39 -> 27433.333 | Q39: =O39/(O39+P39) -> 0 | R39: =F39*O39 -> 0 | S39: =J39*P39 -> 0 | T39: =((S39+R39)/(Q$4*M$6+M$7)/60)*Z39 -> 0 | U39: =T39/T$15 -> 0 | Z39: ='Glider Parameters'!F43 -> 0
A40: =A38+1 -> 24 | B40: Spare Sensor | C40: 2 | D40: =$D$10 -> 10.8 | E40: 0 | F40: =D40*E40 -> 0 | K40: =L40/(2-'Glider Parameters'!F$35) -> 2211.1111 | L40: =Q$4*60 -> 4422.2222 | M40: 0 | N40: =M$7*60 -> 900 | O40: =(Q$4*60*M$6)/L40*K40+M$7*60/N40*M40 -> 13266.667 | P40: =(Q$4*M$6+M$7)*60-O40 -> 14166.667 | Q40: =O40/(O40+P40) -> 0.4835966 | R40: =F40*O40 -> 0 | S40: =J40*P40 -> 0 | T40: =((S40+R40)/(Q$4*M$6+M$7)/60)*Z40 -> 0 | U40: =T40/T$15 -> 0 | Z40: ='Glider Parameters'!F44 -> 0
...
